<?xml version='1.0'?>
<%
  # Parameterized gearbox demo
  require "matrix"
  def a_to_s(v)
    Array(v).join(" ")
  end

  # default density of Aluminum in kg/m^3
  def box_inertia(dx, dy, dz, density=2700)
    box = {}
    box[:size]   = Vector[dx, dy, dz]
    box[:volume] = dx * dy * dz
    box[:mass] = density * box[:volume]
    box[:ixx]  = box[:mass]/12.0 * (dy**2 + dz**2)
    box[:iyy]  = box[:mass]/12.0 * (dz**2 + dx**2)
    box[:izz]  = box[:mass]/12.0 * (dx**2 + dy**2)
    box
  end
  boxes = {}

  boxes["input_body"] = box_inertia(1, 1, 1, density=1)
  boxes["output_body"] = box_inertia(1, 1, 1, density=1)
%>
<sdf version='1.6'>
  <model name='gearbox_demo'>
    <pose>0 0 1.5 0 <%= Math::PI / 2 %> 0</pose>
    <link name='input_body'>
      <inertial>
        <mass><%= boxes["input_body"][:mass] %></mass>
        <inertia>
          <ixx><%= boxes["input_body"][:ixx] %></ixx>
          <ixy>0</ixy>
          <ixz>0</ixz>
          <iyy><%= boxes["input_body"][:iyy] %></iyy>
          <iyz>0</iyz>
          <izz><%= boxes["input_body"][:izz] %></izz>
        </inertia>
      </inertial>
      <pose frame=''>1 0 0 0 -0 0</pose>
      <visual name='visual'>
        <pose frame=''>0 0 0 0 -0 0</pose>
        <geometry>
          <box>
            <size>1 1 1</size>
          </box>
        </geometry>
        <material>
          <script>
            <uri>file://media/materials/scripts/gazebo.material</uri>
            <name>Gazebo/Grey</name>
          </script>
        </material>
      </visual>
      <collision name='collision'>
        <geometry>
          <box>
            <size>1 1 1</size>
          </box>
        </geometry>
      </collision>
    </link>
    <link name='motor_shaft'>
      <inertial>
        <mass>0.151642</mass>
        <inertia>
          <ixx>0.0189553</ixx>
          <ixy>0</ixy>
          <ixz>0</ixz>
          <iyy>0.00976825</iyy>
          <iyz>0</iyz>
          <izz>0.00976825</izz>
        </inertia>
        <pose frame=''>0 0 0 0 -0 0</pose>
      </inertial>
      <visual name='visual'>
        <pose frame=''>0 0 0 0 <%= Math::PI / 2 %> 0</pose>
        <geometry>
          <cylinder>
            <radius>0.5</radius>
            <length>0.151644</length>
          </cylinder>
        </geometry>
        <material>
          <script>
            <uri>file://media/materials/scripts/gazebo.material</uri>
            <name>Gazebo/Grey</name>
          </script>
        </material>
      </visual>
      <collision name='collision'>
        <pose frame=''>0 0 0 0 <%= Math::PI / 2 %> 0</pose>
        <geometry>
          <cylinder>
            <radius>0.5</radius>
            <length>0.151644</length>
          </cylinder>
        </geometry>
      </collision>
    </link>
    <link name='output_body'>
      <inertial>
        <mass><%= boxes["output_body"][:mass] %></mass>
        <inertia>
          <ixx><%= boxes["output_body"][:ixx] %></ixx>
          <ixy>0</ixy>
          <ixz>0</ixz>
          <iyy><%= boxes["output_body"][:iyy] %></iyy>
          <iyz>0</iyz>
          <izz><%= boxes["output_body"][:izz] %></izz>
        </inertia>
      </inertial>
      <pose frame=''>-1 0 0 0 -0 0</pose>
      <visual name='visual'>
        <geometry>
          <box>
            <size>1 1 1</size>
          </box>
        </geometry>
        <material>
          <script>
            <uri>file://media/materials/scripts/gazebo.material</uri>
            <name>Gazebo/Grey</name>
          </script>
        </material>
      </visual>
      <collision name='collision'>
        <geometry>
          <box>
            <size>1 1 1</size>
          </box>
        </geometry>
      </collision>
    </link>
    <joint name='input_joint' type='revolute'>
      <parent>motor_shaft</parent>
      <child>input_body</child>
      <pose frame=''>0 0 0 0 -0 0</pose>
      <axis>
        <xyz>1 0 0</xyz>
        <dynamics>
          <spring_reference>0</spring_reference>
          <spring_stiffness>0</spring_stiffness>
          <damping>1</damping>
          <friction>0</friction>
        </dynamics>
      </axis>
      <physics>
        <ode>
          <limit>
            <cfm>0</cfm>
            <erp>0.2</erp>
          </limit>
          <suspension>
            <cfm>0</cfm>
            <erp>0.2</erp>
          </suspension>
        </ode>
      </physics>
    </joint>
    <joint name='output_joint' type='revolute'>
      <parent>output_body</parent>
      <child>motor_shaft</child>
      <pose frame=''>0 0 0 0 -0 0</pose>
      <axis>
        <xyz>1 0 0</xyz>
      </axis>
        <dynamics>
          <spring_reference>0</spring_reference>
          <spring_stiffness>0</spring_stiffness>
          <damping>1</damping>
          <friction>0</friction>
        </dynamics>
    </joint>
    <joint name='output_reduction' type='gearbox'>
      <parent>motor_shaft</parent>
      <child>output_body</child>
      <gearbox_ratio>-0.1</gearbox_ratio>
      <gearbox_reference_body>input_body</gearbox_reference_body>
      <axis>
        <xyz>1 0 0</xyz>
      </axis>
      <axis2>
        <xyz>1 0 0</xyz>
      </axis2>
    </joint>
  </model>
</sdf>
